<?xml version='1.0'?>


<robot name="my_robot" xmlns:xacro="http://ros.org/wiki/xacro">

  <xacro:property name="scale" value="7 7 7" />

	<link name="lower_left_rim_link">

		<inertial>

			<origin xyz="0 0 -0.000343"/>
			<mass value="2"/>
			<inertia
				ixx=".6"
				ixy="0"
				ixz="0"
				iyy=".6"
				iyz="0"
				izz=".9"
			/>

		</inertial>
		<visual>
                        <origin xyz="0 0.01 0" rpy="1.570795 0 0" />
			<geometry>

				<mesh filename="package://myrobot_description/meshes/rim.stl" scale="${scale}"/>

			</geometry>
			<material name="lower_left_rim_material">

				<color rgba="0.3 0 0 1"/>

			</material>

		</visual>
		<collision>
                        <origin xyz="0 0.01 0" rpy="1.570795 0 0" />
			<geometry>

				<mesh filename="package://myrobot_description/meshes/rim.stl" scale="${scale}"/>

			</geometry>

		</collision>

	</link>
	<joint
		name="joint_lower_left_wheel"
		type="continuous"
	>

		<parent link="base_link"/>
		<child link="lower_left_rim_link"/>
		<axis xyz="0 1 0 "/>
		<origin
			xyz="-0.15 0.30 -0.5"
			rpy="0 0 0"
		/>

	</joint>
	<link name="lower_left_roller_e_link">

		<inertial>

			<mass value="0.00113845"/>
			<inertia
				ixx="2.53776e-08"
				ixy="0"
				ixz="0"
				iyy="2.53776e-08"
				iyz="0"
				izz="1.47666e-08"
			/>

		</inertial>
		<visual>
		<origin xyz="0 0 0" rpy="0.7853981633974483 0  1.570795 "/>
			<geometry>

				<mesh filename="package://myrobot_description/meshes/roller.stl" scale="${scale}"/>

			</geometry>
			<material name="lower_left_roller_e_material">

				<color rgba="0.03 0.03 0.03 1"/>

			</material>

		</visual>
		<collision>
		<origin xyz="0 0 0" rpy="0 1.570795 0"/>
			<geometry>

				<mesh filename="package://myrobot_description/meshes/roller.stl" scale="${scale}"/>

			</geometry>

		</collision>

	</link>
	<joint
		name="lower_left_roller_e_joint"
		type="continuous"
	>

		<parent link="lower_left_rim_link"/>
		<child link="lower_left_roller_e_link"/>
		<axis xyz="0 1 0"/>
		<origin
			xyz="0.09485 0 0.0385"
			rpy="0 0  0"
		/>

	</joint>
	<link name="lower_left_roller_ne_link">

		<inertial>

			<mass value="0.00113845"/>
			<inertia
				ixx="2.53776e-08"
				ixy="0"
				ixz="0"
				iyy="2.53776e-08"
				iyz="0"
				izz="1.47666e-08"
			/>

		</inertial>
		<visual>

			<geometry>

				<mesh filename="package://myrobot_description/meshes/roller.stl" scale="${scale}"/>

			</geometry>
			<material name="lower_left_roller_e_material">

				<color rgba="0.03 0.03 0.03 1"/>

			</material>

		</visual>
		<collision>

			<geometry>

				<mesh filename="package://myrobot_description/meshes/roller.stl" scale="${scale}"/>

			</geometry>

		</collision>

	</link>
	<joint
		name="lower_left_roller_ne_joint"
		type="continuous"
	>

		<parent link="lower_left_rim_link"/>
		<child link="lower_left_roller_ne_link"/>
		<axis xyz="0 0 1"/>
		<origin
			xyz="0.00958129689 0.00958129689 -0.0055"
			rpy="-1.570796326794896 0 0.7853981633974483"
		/>

	</joint>
	<link name="lower_left_roller_n_link">

		<inertial>

			<mass value="0.00113845"/>
			<inertia
				ixx="2.53776e-08"
				ixy="0"
				ixz="0"
				iyy="2.53776e-08"
				iyz="0"
				izz="1.47666e-08"
			/>

		</inertial>
		<visual>

			<geometry>

				<mesh filename="package://myrobot_description/meshes/roller.stl" scale="${scale}"/>

			</geometry>
			<material name="lower_left_roller_n_material">

				<color rgba="0.03 0.03 0.03 1"/>

			</material>

		</visual>
		<collision>

			<geometry>

				<mesh filename="package://myrobot_description/meshes/roller.stl" scale="${scale}"/>

			</geometry>

		</collision>

	</link>
	<joint
		name="lower_left_roller_n_joint"
		type="continuous"
	>

		<parent link="lower_left_rim_link"/>
		<child link="lower_left_roller_n_link"/>
		<axis xyz="0 0 1"/>
		<origin
			xyz="0 0.01355 0.0055"
			rpy="-1.570796326794896 0 1.570796326794896"
		/>

	</joint>
	<link name="lower_left_roller_nw_link">

		<inertial>

			<mass value="0.00113845"/>
			<inertia
				ixx="2.53776e-08"
				ixy="0"
				ixz="0"
				iyy="2.53776e-08"
				iyz="0"
				izz="1.47666e-08"
			/>

		</inertial>
		<visual>

			<geometry>

				<mesh filename="package://myrobot_description/meshes/roller.stl" scale="${scale}"/>

			</geometry>
			<material name="lower_left_roller_nw_material">

				<color rgba="0.03 0.03 0.03 1"/>

			</material>

		</visual>
		<collision>

			<geometry>

				<mesh filename="package://myrobot_description/meshes/roller.stl" scale="${scale}"/>

			</geometry>

		</collision>

	</link>
	<joint
		name="lower_left_roller_nw_joint"
		type="continuous"
	>

		<parent link="lower_left_rim_link"/>
		<child link="lower_left_roller_nw_link"/>
		<axis xyz="0 0 1"/>
		<origin
			xyz="-0.00958129689 0.00958129689 -0.0055"
			rpy="-1.570796326794896 0 2.356194490192345"
		/>

	</joint>
	<link name="lower_left_roller_w_link">

		<inertial>

			<mass value="0.00113845"/>
			<inertia
				ixx="2.53776e-08"
				ixy="0"
				ixz="0"
				iyy="2.53776e-08"
				iyz="0"
				izz="1.47666e-08"
			/>

		</inertial>
		<visual>

			<geometry>

				<mesh filename="package://myrobot_description/meshes/roller.stl" scale="${scale}"/>

			</geometry>
			<material name="lower_left_roller_w_material">

				<color rgba="0.03 0.03 0.03 1"/>

			</material>

		</visual>
		<collision>

			<geometry>

				<mesh filename="package://myrobot_description/meshes/roller.stl" scale="${scale}"/>

			</geometry>

		</collision>

	</link>
	<joint
		name="lower_left_roller_w_joint"
		type="continuous"
	>

		<parent link="lower_left_rim_link"/>
		<child link="lower_left_roller_w_link"/>
		<axis xyz="0 0 1"/>
		<origin
			xyz="-0.01355 0 0.0055"
			rpy="-1.570796326794896 0 3.141592653589793"
		/>

	</joint>
	<link name="lower_left_roller_sw_link">

		<inertial>

			<mass value="0.00113845"/>
			<inertia
				ixx="2.53776e-08"
				ixy="0"
				ixz="0"
				iyy="2.53776e-08"
				iyz="0"
				izz="1.47666e-08"
			/>

		</inertial>
		<visual>

			<geometry>

				<mesh filename="package://myrobot_description/meshes/roller.stl" scale="${scale}"/>

			</geometry>
			<material name="lower_left_roller_sw_material">

				<color rgba="0.03 0.03 0.03 1"/>

			</material>

		</visual>
		<collision>

			<geometry>

				<mesh filename="package://myrobot_description/meshes/roller.stl" scale="${scale}"/>

			</geometry>

		</collision>

	</link>
	<joint
		name="lower_left_roller_sw_joint"
		type="continuous"
	>

		<parent link="lower_left_rim_link"/>
		<child link="lower_left_roller_sw_link"/>
		<axis xyz="0 0 1"/>
		<origin
			xyz="-0.00958129689 -0.00958129689 -0.0055"
			rpy="-1.570796326794896 0 -2.356194490192345"
		/>

	</joint>
	<link name="lower_left_roller_s_link">

		<inertial>

			<mass value="0.00113845"/>
			<inertia
				ixx="2.53776e-08"
				ixy="0"
				ixz="0"
				iyy="2.53776e-08"
				iyz="0"
				izz="1.47666e-08"
			/>

		</inertial>
		<visual>

			<geometry>

				<mesh filename="package://myrobot_description/meshes/roller.stl" scale="${scale}"/>

			</geometry>
			<material name="lower_left_roller_s_material">

				<color rgba="0.03 0.03 0.03 1"/>

			</material>

		</visual>
		<collision>

			<geometry>

				<mesh filename="package://myrobot_description/meshes/roller.stl" scale="${scale}"/>

			</geometry>

		</collision>

	</link>
	<joint
		name="lower_left_roller_s_joint"
		type="continuous"
	>

		<parent link="lower_left_rim_link"/>
		<child link="lower_left_roller_s_link"/>
		<axis xyz="0 0 1"/>
		<origin
			xyz="0 -0.01355 0.0055"
			rpy="-1.570796326794896 0 -1.570796326794896"
		/>

	</joint>
	<link name="lower_left_roller_se_link">

		<inertial>

			<mass value="0.00113845"/>
			<inertia
				ixx="2.53776e-08"
				ixy="0"
				ixz="0"
				iyy="2.53776e-08"
				iyz="0"
				izz="1.47666e-08"
			/>

		</inertial>
		<visual>

			<geometry>

				<mesh filename="package://myrobot_description/meshes/roller.stl" scale="${scale}"/>

			</geometry>
			<material name="lower_left_roller_se_material">

				<color rgba="0.03 0.03 0.03 1"/>

			</material>

		</visual>
		<collision>

			<geometry>

				<mesh filename="package://myrobot_description/meshes/roller.stl" scale="${scale}"/>

			</geometry>

		</collision>

	</link>
	<joint
		name="lower_left_roller_se_joint"
		type="continuous"
	>

		<parent link="lower_left_rim_link"/>
		<child link="lower_left_roller_se_link"/>
		<axis xyz="0 0 1"/>
		<origin
			xyz="0.00958129689 -0.00958129689 -0.0055"
			rpy="-1.570796326794896 0 -0.7853981633974483"
		/>

	</joint>
<!-- right -->

	<link name="lower_right_rim_link">

		<inertial>

			<origin xyz="0 0 -0.000343"/>
			<mass value="2"/>
			<inertia
				ixx="0.6"
				ixy="0"
				ixz="0"
				iyy="0.6"
				iyz="0"
				izz="0.9"
			/>

		</inertial>
		<visual>
                        <origin xyz="0 -0.01 0" rpy="1.570795 0 0" />
			<geometry>

				<mesh filename="package://myrobot_description/meshes/rim.stl" scale="${scale}"/>

			</geometry>
			<material name="lower_right_rim_material">

				<color rgba="0.3 0 0 1"/>

			</material>

		</visual>
		<collision>
                        <origin xyz="0 -0.01 0" rpy="1.570795 0 0" />
			<geometry>

				<mesh filename="package://myrobot_description/meshes/rim.stl" scale="${scale}"/>

			</geometry>

		</collision>

	</link>
	<joint
		name="joint_lower_right_wheel"
		type="continuous"
	>

		<parent link="base_link"/>
		<child link="lower_right_rim_link"/>
		<axis xyz="0 1 0"/>
		<origin
			xyz="-0.15 -0.3 -0.5"
			rpy="0 0 0"
		/>

	</joint>
	<link name="lower_right_roller_e_link">

		<inertial>

			<mass value="0.00113845"/>
			<inertia
				ixx="2.53776e-08"
				ixy="0"
				ixz="0"
				iyy="2.53776e-08"
				iyz="0"
				izz="1.47666e-08"
			/>

		</inertial>
		<visual>

			<geometry>

				<mesh filename="package://myrobot_description/meshes/roller.stl" scale="${scale}"/>

			</geometry>
			<material name="lower_right_roller_e_material">

				<color rgba="0.03 0.03 0.03 1"/>

			</material>

		</visual>
		<collision>

			<geometry>

				<mesh filename="package://myrobot_description/meshes/roller.stl" scale="${scale}"/>

			</geometry>

		</collision>

	</link>
	<joint
		name="lower_right_roller_e_joint"
		type="continuous"
	>

		<parent link="lower_right_rim_link"/>
		<child link="lower_right_roller_e_link"/>
		<axis xyz="0 0 1"/>
		<origin
			xyz="0.01355 0 0.0055"
			rpy="-1.570796326794896 0 0"
		/>

	</joint>
	<link name="lower_right_roller_ne_link">

		<inertial>

			<mass value="0.00113845"/>
			<inertia
				ixx="2.53776e-08"
				ixy="0"
				ixz="0"
				iyy="2.53776e-08"
				iyz="0"
				izz="1.47666e-08"
			/>

		</inertial>
		<visual>

			<geometry>

				<mesh filename="package://myrobot_description/meshes/roller.stl" scale="${scale}"/>

			</geometry>
			<material name="lower_right_roller_e_material">

				<color rgba="0.03 0.03 0.03 1"/>

			</material>

		</visual>
		<collision>

			<geometry>

				<mesh filename="package://myrobot_description/meshes/roller.stl" scale="${scale}"/>

			</geometry>

		</collision>

	</link>
	<joint
		name="lower_right_roller_ne_joint"
		type="continuous"
	>

		<parent link="lower_right_rim_link"/>
		<child link="lower_right_roller_ne_link"/>
		<axis xyz="0 0 1"/>
		<origin
			xyz="0.00958129689 0.00958129689 -0.0055"
			rpy="-1.570796326794896 0 0.7853981633974483"
		/>

	</joint>
	<link name="lower_right_roller_n_link">

		<inertial>

			<mass value="0.00113845"/>
			<inertia
				ixx="2.53776e-08"
				ixy="0"
				ixz="0"
				iyy="2.53776e-08"
				iyz="0"
				izz="1.47666e-08"
			/>

		</inertial>
		<visual>

			<geometry>

				<mesh filename="package://myrobot_description/meshes/roller.stl" scale="${scale}"/>

			</geometry>
			<material name="lower_right_roller_n_material">

				<color rgba="0.03 0.03 0.03 1"/>

			</material>

		</visual>
		<collision>

			<geometry>

				<mesh filename="package://myrobot_description/meshes/roller.stl" scale="${scale}"/>

			</geometry>

		</collision>

	</link>
	<joint
		name="lower_right_roller_n_joint"
		type="continuous"
	>

		<parent link="lower_right_rim_link"/>
		<child link="lower_right_roller_n_link"/>
		<axis xyz="0 0 1"/>
		<origin
			xyz="0 0.01355 0.0055"
			rpy="-1.570796326794896 0 1.570796326794896"
		/>

	</joint>
	<link name="lower_right_roller_nw_link">

		<inertial>

			<mass value="0.00113845"/>
			<inertia
				ixx="2.53776e-08"
				ixy="0"
				ixz="0"
				iyy="2.53776e-08"
				iyz="0"
				izz="1.47666e-08"
			/>

		</inertial>
		<visual>

			<geometry>

				<mesh filename="package://myrobot_description/meshes/roller.stl" scale="${scale}"/>

			</geometry>
			<material name="lower_right_roller_nw_material">

				<color rgba="0.03 0.03 0.03 1"/>

			</material>

		</visual>
		<collision>

			<geometry>

				<mesh filename="package://myrobot_description/meshes/roller.stl" scale="${scale}"/>

			</geometry>

		</collision>

	</link>
	<joint
		name="lower_right_roller_nw_joint"
		type="continuous"
	>

		<parent link="lower_right_rim_link"/>
		<child link="lower_right_roller_nw_link"/>
		<axis xyz="0 0 1"/>
		<origin
			xyz="-0.00958129689 0.00958129689 -0.0055"
			rpy="-1.570796326794896 0 2.356194490192345"
		/>

	</joint>
	<link name="lower_right_roller_w_link">

		<inertial>

			<mass value="0.00113845"/>
			<inertia
				ixx="2.53776e-08"
				ixy="0"
				ixz="0"
				iyy="2.53776e-08"
				iyz="0"
				izz="1.47666e-08"
			/>

		</inertial>
		<visual>

			<geometry>

				<mesh filename="package://myrobot_description/meshes/roller.stl" scale="${scale}"/>

			</geometry>
			<material name="lower_right_roller_w_material">

				<color rgba="0.03 0.03 0.03 1"/>

			</material>

		</visual>
		<collision>

			<geometry>

				<mesh filename="package://myrobot_description/meshes/roller.stl" scale="${scale}"/>

			</geometry>

		</collision>

	</link>
	<joint
		name="lower_right_roller_w_joint"
		type="continuous"
	>

		<parent link="lower_right_rim_link"/>
		<child link="lower_right_roller_w_link"/>
		<axis xyz="0 0 1"/>
		<origin
			xyz="-0.01355 0 0.0055"
			rpy="-1.570796326794896 0 3.141592653589793"
		/>

	</joint>
	<link name="lower_right_roller_sw_link">

		<inertial>

			<mass value="0.00113845"/>
			<inertia
				ixx="2.53776e-08"
				ixy="0"
				ixz="0"
				iyy="2.53776e-08"
				iyz="0"
				izz="1.47666e-08"
			/>

		</inertial>
		<visual>

			<geometry>

				<mesh filename="package://myrobot_description/meshes/roller.stl" scale="${scale}"/>

			</geometry>
			<material name="lower_right_roller_sw_material">

				<color rgba="0.03 0.03 0.03 1"/>

			</material>

		</visual>
		<collision>

			<geometry>

				<mesh filename="package://myrobot_description/meshes/roller.stl" scale="${scale}"/>

			</geometry>

		</collision>

	</link>
	<joint
		name="lower_right_roller_sw_joint"
		type="continuous"
	>

		<parent link="lower_right_rim_link"/>
		<child link="lower_right_roller_sw_link"/>
		<axis xyz="0 0 1"/>
		<origin
			xyz="-0.00958129689 -0.00958129689 -0.0055"
			rpy="-1.570796326794896 0 -2.356194490192345"
		/>

	</joint>
	<link name="lower_right_roller_s_link">

		<inertial>

			<mass value="0.00113845"/>
			<inertia
				ixx="2.53776e-08"
				ixy="0"
				ixz="0"
				iyy="2.53776e-08"
				iyz="0"
				izz="1.47666e-08"
			/>

		</inertial>
		<visual>

			<geometry>

				<mesh filename="package://myrobot_description/meshes/roller.stl" scale="${scale}"/>

			</geometry>
			<material name="lower_right_roller_s_material">

				<color rgba="0.03 0.03 0.03 1"/>

			</material>

		</visual>
		<collision>

			<geometry>

				<mesh filename="package://myrobot_description/meshes/roller.stl" scale="${scale}"/>

			</geometry>

		</collision>

	</link>
	<joint
		name="lower_right_roller_s_joint"
		type="continuous"
	>

		<parent link="lower_right_rim_link"/>
		<child link="lower_right_roller_s_link"/>
		<axis xyz="0 0 1"/>
		<origin
			xyz="0 -0.01355 0.0055"
			rpy="-1.570796326794896 0 -1.570796326794896"
		/>

	</joint>
	<link name="lower_right_roller_se_link">

		<inertial>

			<mass value="0.00113845"/>
			<inertia
				ixx="2.53776e-08"
				ixy="0"
				ixz="0"
				iyy="2.53776e-08"
				iyz="0"
				izz="1.47666e-08"
			/>

		</inertial>
		<visual>

			<geometry>

				<mesh filename="package://myrobot_description/meshes/roller.stl" scale="${scale}"/>

			</geometry>
			<material name="lower_right_roller_se_material">

				<color rgba="0.03 0.03 0.03 1"/>

			</material>

		</visual>
		<collision>

			<geometry>

				<mesh filename="package://myrobot_description/meshes/roller.stl" scale="${scale}"/>

			</geometry>

		</collision>

	</link>
	<joint
		name="lower_right_roller_se_joint"
		type="continuous"
	>

		<parent link="lower_right_rim_link"/>
		<child link="lower_right_roller_se_link"/>
		<axis xyz="0 0 1"/>
		<origin
			xyz="0.00958129689 -0.00958129689 -0.0055"
			rpy="-1.570796326794896 0 -0.7853981633974483"
		/>

	</joint>


</robot>



